Exception in thread Thread-2:
Traceback (most recent call last):
  File "/usr/lib/python3/dist-packages/serial/serialposix.py", line 265, in open
    self.fd = os.open(self.portstr, os.O_RDWR | os.O_NOCTTY | os.O_NONBLOCK)
PermissionError: [Errno 13] Permission denied: '/dev/ttyS10'

During handling of the above exception, another exception occurred:

Traceback (most recent call last):
  File "/usr/lib/python3.6/threading.py", line 916, in _bootstrap_inner
    self.run()
  File "/usr/lib/python3.6/threading.py", line 864, in run
    self._target(*self._args, **self._kwargs)
  File "src/ThreadedWindow.py", line 72, in receive_data
    self.radio.receive()
  File "/mnt/c/users/mrdro/orbit/Ground-Station-GUI/src/communications/RadioModule.py", line 73, in receive
    self.device.open()
  File "/usr/local/lib/python3.6/dist-packages/digi/xbee/devices.py", line 1245, in open
    self._serial_port.open()
  File "/usr/lib/python3/dist-packages/serial/serialposix.py", line 268, in open
    raise SerialException(msg.errno, "could not open port {}: {}".format(self._port, msg))
serial.serialutil.SerialException: [Errno 13] could not open port /dev/ttyS10: [Errno 13] Permission denied: '/dev/ttyS10'

Exception in Tkinter callback
Traceback (most recent call last):
  File "/mnt/c/users/mrdro/orbit/Ground-Station-GUI/src/DataWindow.py", line 355, in process_incoming
    self.data.temperature_data = data_json["temperature"]
AttributeError: 'DataWindow' object has no attribute 'data'

During handling of the above exception, another exception occurred:

Traceback (most recent call last):
  File "/usr/lib/python3.6/tkinter/__init__.py", line 1702, in __call__
    return self.func(*args)
  File "/usr/lib/python3.6/tkinter/__init__.py", line 746, in callit
    func(*args)
  File "src/ThreadedWindow.py", line 57, in update
    self.gui.process_incoming()
  File "/mnt/c/users/mrdro/orbit/Ground-Station-GUI/src/DataWindow.py", line 365, in process_incoming
    except self.queue.Empty:
AttributeError: 'Queue' object has no attribute 'Empty'
Exception in Tkinter callback
Traceback (most recent call last):
  File "/usr/lib/python3.6/tkinter/__init__.py", line 1702, in __call__
    return self.func(*args)
  File "/mnt/c/users/mrdro/orbit/Ground-Station-GUI/src/DataWindow.py", line 170, in start_mission
    Comm.get_instance().testing()
TypeError: get_instance() missing 1 required positional argument: 'self'
